<?xml version="1.0" ?>
<robot name="car" xmlns:xacro="http://www.ros.org/wiki/xacro">

<xacro:include filename="$(find car_description)/urdf/materials.xacro" />
<xacro:include filename="$(find car_description)/urdf/car.trans" />
<xacro:include filename="$(find car_description)/urdf/car.gazebo" />
<link name="base_link">
  <inertial>
    <origin xyz="6.544927660584173e-10 0.0006698714182109139 0.019995204416368553" rpy="0 0 0"/>
    <mass value="1.7358186551507793"/>
    <inertia ixx="0.011281" iyy="0.003164" izz="0.013974" ixy="-0.0" iyz="1e-06" ixz="0.0"/>
  </inertial>
  <visual>
    <origin xyz="0 0 0" rpy="0 0 0"/>
    <geometry>
      <mesh filename="file://$(find car_description)/meshes/base_link.stl" scale="0.001 0.001 0.001"/>
    </geometry>
    <material name="silver"/>
  </visual>
  <collision>
    <origin xyz="0 0 0" rpy="0 0 0"/>
    <geometry>
      <mesh filename="file://$(find car_description)/meshes/base_link.stl" scale="0.001 0.001 0.001"/>
    </geometry>
  </collision>
</link>

<link name="left_wheel_1">
  <inertial>
    <origin xyz="-0.007499999999999979 1.4901158085223187e-10 1.734723475976807e-17" rpy="0 0 0"/>
    <mass value="0.07012034802812418"/>
    <inertia ixx="5.6e-05" iyy="2.9e-05" izz="2.9e-05" ixy="-0.0" iyz="0.0" ixz="0.0"/>
  </inertial>
  <visual>
    <origin xyz="0.08 0.07 -0.02" rpy="0 0 0"/>
    <geometry>
      <mesh filename="file://$(find car_description)/meshes/left_wheel_1.stl" scale="0.001 0.001 0.001"/>
    </geometry>
    <material name="silver"/>
  </visual>
  <collision>
    <origin xyz="0.08 0.07 -0.02" rpy="0 0 0"/>
    <geometry>
      <mesh filename="file://$(find car_description)/meshes/left_wheel_1.stl" scale="0.001 0.001 0.001"/>
    </geometry>
  </collision>
</link>

<link name="right_wheel_1">
  <inertial>
    <origin xyz="0.007499999999999979 1.4901159473001968e-10 3.8163916471489756e-17" rpy="0 0 0"/>
    <mass value="0.07012034802812418"/>
    <inertia ixx="5.6e-05" iyy="2.9e-05" izz="2.9e-05" ixy="0.0" iyz="0.0" ixz="0.0"/>
  </inertial>
  <visual>
    <origin xyz="-0.08 0.07 -0.02" rpy="0 0 0"/>
    <geometry>
      <mesh filename="file://$(find car_description)/meshes/right_wheel_1.stl" scale="0.001 0.001 0.001"/>
    </geometry>
    <material name="silver"/>
  </visual>
  <collision>
    <origin xyz="-0.08 0.07 -0.02" rpy="0 0 0"/>
    <geometry>
      <mesh filename="file://$(find car_description)/meshes/right_wheel_1.stl" scale="0.001 0.001 0.001"/>
    </geometry>
  </collision>
</link>

<link name="lidar_1">
  <inertial>
    <origin xyz="-3.769546289141941e-18 1.3877787807814457e-17 0.015" rpy="0 0 0"/>
    <mass value="0.03996105855366222"/>
    <inertia ixx="7e-06" iyy="7e-06" izz="8e-06" ixy="-0.0" iyz="0.0" ixz="-0.0"/>
  </inertial>
  <visual>
    <origin xyz="-0.0 -0.1 -0.045" rpy="0 0 0"/>
    <geometry>
      <mesh filename="file://$(find car_description)/meshes/lidar_1.stl" scale="0.001 0.001 0.001"/>
    </geometry>
    <material name="silver"/>
  </visual>
  <collision>
    <origin xyz="-0.0 -0.1 -0.045" rpy="0 0 0"/>
    <geometry>
      <mesh filename="file://$(find car_description)/meshes/lidar_1.stl" scale="0.001 0.001 0.001"/>
    </geometry>
  </collision>
</link>

<joint name="Revolute 1" type="continuous">
  <origin xyz="-0.08 -0.07 0.02" rpy="0 0 0"/>
  <parent link="base_link"/>
  <child link="left_wheel_1"/>
  <axis xyz="-1.0 -0.0 0.0"/>
</joint>

<joint name="Revolute 2" type="continuous">
  <origin xyz="0.08 -0.07 0.02" rpy="0 0 0"/>
  <parent link="base_link"/>
  <child link="right_wheel_1"/>
  <axis xyz="1.0 -0.0 0.0"/>
</joint>

<joint name="Rigid 3" type="fixed">
  <origin xyz="0.0 0.1 0.045" rpy="0 0 0"/>
  <parent link="base_link"/>
  <child link="lidar_1"/>
</joint>

</robot>
